2016-11-07 08:51:19,989 [Thread-40:8624] [django.request:124] [exception:handle_uncaught_exception] [ERROR]- Internal Server Error: /project/
Traceback (most recent call last):
  File "C:\Python27\lib\site-packages\django\core\handlers\exception.py", line 39, in inner
    response = get_response(request)
  File "C:\Python27\lib\site-packages\django\core\handlers\base.py", line 187, in _get_response
    response = self.process_exception_by_middleware(e, request)
  File "C:\Python27\lib\site-packages\django\core\handlers\base.py", line 185, in _get_response
    response = wrapped_callback(request, *callback_args, **callback_kwargs)
  File "C:\Python27\lib\site-packages\django\views\decorators\csrf.py", line 58, in wrapped_view
    return view_func(*args, **kwargs)
TypeError: project() takes exactly 1 argument (2 given)
2016-11-07 08:51:23,292 [Thread-41:8612] [django.request:124] [exception:handle_uncaught_exception] [ERROR]- Internal Server Error: /project/
Traceback (most recent call last):
  File "C:\Python27\lib\site-packages\django\core\handlers\exception.py", line 39, in inner
    response = get_response(request)
  File "C:\Python27\lib\site-packages\django\core\handlers\base.py", line 187, in _get_response
    response = self.process_exception_by_middleware(e, request)
  File "C:\Python27\lib\site-packages\django\core\handlers\base.py", line 185, in _get_response
    response = wrapped_callback(request, *callback_args, **callback_kwargs)
  File "C:\Python27\lib\site-packages\django\views\decorators\csrf.py", line 58, in wrapped_view
    return view_func(*args, **kwargs)
TypeError: project() takes exactly 1 argument (2 given)
2016-11-07 08:51:23,500 [Thread-42:8436] [django.request:124] [exception:handle_uncaught_exception] [ERROR]- Internal Server Error: /project/
Traceback (most recent call last):
  File "C:\Python27\lib\site-packages\django\core\handlers\exception.py", line 39, in inner
    response = get_response(request)
  File "C:\Python27\lib\site-packages\django\core\handlers\base.py", line 187, in _get_response
    response = self.process_exception_by_middleware(e, request)
  File "C:\Python27\lib\site-packages\django\core\handlers\base.py", line 185, in _get_response
    response = wrapped_callback(request, *callback_args, **callback_kwargs)
  File "C:\Python27\lib\site-packages\django\views\decorators\csrf.py", line 58, in wrapped_view
    return view_func(*args, **kwargs)
TypeError: project() takes exactly 1 argument (2 given)
2016-11-07 08:51:23,686 [Thread-43:7260] [django.request:124] [exception:handle_uncaught_exception] [ERROR]- Internal Server Error: /project/
Traceback (most recent call last):
  File "C:\Python27\lib\site-packages\django\core\handlers\exception.py", line 39, in inner
    response = get_response(request)
  File "C:\Python27\lib\site-packages\django\core\handlers\base.py", line 187, in _get_response
    response = self.process_exception_by_middleware(e, request)
  File "C:\Python27\lib\site-packages\django\core\handlers\base.py", line 185, in _get_response
    response = wrapped_callback(request, *callback_args, **callback_kwargs)
  File "C:\Python27\lib\site-packages\django\views\decorators\csrf.py", line 58, in wrapped_view
    return view_func(*args, **kwargs)
TypeError: project() takes exactly 1 argument (2 given)
2016-11-07 08:51:27,569 [Thread-82:8936] [django.request:124] [exception:handle_uncaught_exception] [ERROR]- Internal Server Error: /project/
Traceback (most recent call last):
  File "C:\Python27\lib\site-packages\django\core\handlers\exception.py", line 39, in inner
    response = get_response(request)
  File "C:\Python27\lib\site-packages\django\core\handlers\base.py", line 187, in _get_response
    response = self.process_exception_by_middleware(e, request)
  File "C:\Python27\lib\site-packages\django\core\handlers\base.py", line 185, in _get_response
    response = wrapped_callback(request, *callback_args, **callback_kwargs)
  File "C:\Python27\lib\site-packages\django\views\decorators\csrf.py", line 58, in wrapped_view
    return view_func(*args, **kwargs)
TypeError: project() takes exactly 1 argument (2 given)
2016-11-07 08:51:44,821 [Thread-84:9060] [django.request:124] [exception:handle_uncaught_exception] [ERROR]- Internal Server Error: /project/
Traceback (most recent call last):
  File "C:\Python27\lib\site-packages\django\core\handlers\exception.py", line 39, in inner
    response = get_response(request)
  File "C:\Python27\lib\site-packages\django\core\handlers\base.py", line 187, in _get_response
    response = self.process_exception_by_middleware(e, request)
  File "C:\Python27\lib\site-packages\django\core\handlers\base.py", line 185, in _get_response
    response = wrapped_callback(request, *callback_args, **callback_kwargs)
  File "C:\Python27\lib\site-packages\django\views\decorators\csrf.py", line 58, in wrapped_view
    return view_func(*args, **kwargs)
TypeError: project() takes exactly 1 argument (2 given)
2016-11-07 08:51:44,990 [Thread-85:5620] [django.request:124] [exception:handle_uncaught_exception] [ERROR]- Internal Server Error: /project/
Traceback (most recent call last):
  File "C:\Python27\lib\site-packages\django\core\handlers\exception.py", line 39, in inner
    response = get_response(request)
  File "C:\Python27\lib\site-packages\django\core\handlers\base.py", line 187, in _get_response
    response = self.process_exception_by_middleware(e, request)
  File "C:\Python27\lib\site-packages\django\core\handlers\base.py", line 185, in _get_response
    response = wrapped_callback(request, *callback_args, **callback_kwargs)
  File "C:\Python27\lib\site-packages\django\views\decorators\csrf.py", line 58, in wrapped_view
    return view_func(*args, **kwargs)
TypeError: project() takes exactly 1 argument (2 given)
2016-11-07 08:51:45,193 [Thread-86:6472] [django.request:124] [exception:handle_uncaught_exception] [ERROR]- Internal Server Error: /project/
Traceback (most recent call last):
  File "C:\Python27\lib\site-packages\django\core\handlers\exception.py", line 39, in inner
    response = get_response(request)
  File "C:\Python27\lib\site-packages\django\core\handlers\base.py", line 187, in _get_response
    response = self.process_exception_by_middleware(e, request)
  File "C:\Python27\lib\site-packages\django\core\handlers\base.py", line 185, in _get_response
    response = wrapped_callback(request, *callback_args, **callback_kwargs)
  File "C:\Python27\lib\site-packages\django\views\decorators\csrf.py", line 58, in wrapped_view
    return view_func(*args, **kwargs)
TypeError: project() takes exactly 1 argument (2 given)
2016-11-07 08:51:45,375 [Thread-87:7200] [django.request:124] [exception:handle_uncaught_exception] [ERROR]- Internal Server Error: /project/
Traceback (most recent call last):
  File "C:\Python27\lib\site-packages\django\core\handlers\exception.py", line 39, in inner
    response = get_response(request)
  File "C:\Python27\lib\site-packages\django\core\handlers\base.py", line 187, in _get_response
    response = self.process_exception_by_middleware(e, request)
  File "C:\Python27\lib\site-packages\django\core\handlers\base.py", line 185, in _get_response
    response = wrapped_callback(request, *callback_args, **callback_kwargs)
  File "C:\Python27\lib\site-packages\django\views\decorators\csrf.py", line 58, in wrapped_view
    return view_func(*args, **kwargs)
TypeError: project() takes exactly 1 argument (2 given)
2016-11-07 08:51:52,858 [Thread-89:7884] [django.request:124] [exception:handle_uncaught_exception] [ERROR]- Internal Server Error: /project/
Traceback (most recent call last):
  File "C:\Python27\lib\site-packages\django\core\handlers\exception.py", line 39, in inner
    response = get_response(request)
  File "C:\Python27\lib\site-packages\django\core\handlers\base.py", line 187, in _get_response
    response = self.process_exception_by_middleware(e, request)
  File "C:\Python27\lib\site-packages\django\core\handlers\base.py", line 185, in _get_response
    response = wrapped_callback(request, *callback_args, **callback_kwargs)
  File "C:\Python27\lib\site-packages\django\views\decorators\csrf.py", line 58, in wrapped_view
    return view_func(*args, **kwargs)
TypeError: project() takes exactly 1 argument (2 given)
2016-11-07 09:28:09,088 [Thread-95:5200] [django.request:124] [exception:handle_uncaught_exception] [ERROR]- Internal Server Error: /project/
Traceback (most recent call last):
  File "C:\Python27\lib\site-packages\django\core\handlers\exception.py", line 39, in inner
    response = get_response(request)
  File "C:\Python27\lib\site-packages\django\core\handlers\base.py", line 187, in _get_response
    response = self.process_exception_by_middleware(e, request)
  File "C:\Python27\lib\site-packages\django\core\handlers\base.py", line 185, in _get_response
    response = wrapped_callback(request, *callback_args, **callback_kwargs)
  File "C:\Python27\lib\site-packages\django\views\decorators\csrf.py", line 58, in wrapped_view
    return view_func(*args, **kwargs)
TypeError: project() takes exactly 1 argument (2 given)
2016-11-07 09:29:27,315 [Thread-102:6864] [django.request:124] [exception:handle_uncaught_exception] [ERROR]- Internal Server Error: /project/
Traceback (most recent call last):
  File "C:\Python27\lib\site-packages\django\core\handlers\exception.py", line 39, in inner
    response = get_response(request)
  File "C:\Python27\lib\site-packages\django\core\handlers\base.py", line 187, in _get_response
    response = self.process_exception_by_middleware(e, request)
  File "C:\Python27\lib\site-packages\django\core\handlers\base.py", line 185, in _get_response
    response = wrapped_callback(request, *callback_args, **callback_kwargs)
  File "C:\Python27\lib\site-packages\django\views\decorators\csrf.py", line 58, in wrapped_view
    return view_func(*args, **kwargs)
TypeError: project() takes exactly 1 argument (2 given)
2016-11-07 09:34:31,516 [Thread-40:8656] [django.request:124] [exception:handle_uncaught_exception] [ERROR]- Internal Server Error: /project/
Traceback (most recent call last):
  File "C:\Python27\lib\site-packages\django\core\handlers\exception.py", line 39, in inner
    response = get_response(request)
  File "C:\Python27\lib\site-packages\django\core\handlers\base.py", line 187, in _get_response
    response = self.process_exception_by_middleware(e, request)
  File "C:\Python27\lib\site-packages\django\core\handlers\base.py", line 185, in _get_response
    response = wrapped_callback(request, *callback_args, **callback_kwargs)
  File "C:\Python27\lib\site-packages\django\views\decorators\csrf.py", line 58, in wrapped_view
    return view_func(*args, **kwargs)
  File "D:\eclipsworkdir\Automation_Platform\autoDjango\views.py", line 41, in project
    return render(request, 'html/project_list.html', locals())
  File "C:\Python27\lib\site-packages\django\shortcuts.py", line 30, in render
    content = loader.render_to_string(template_name, context, request, using=using)
  File "C:\Python27\lib\site-packages\django\template\loader.py", line 67, in render_to_string
    template = get_template(template_name, using=using)
  File "C:\Python27\lib\site-packages\django\template\loader.py", line 25, in get_template
    raise TemplateDoesNotExist(template_name, chain=chain)
TemplateDoesNotExist: html/project_list.html
2016-11-07 09:35:30,174 [Thread-41:8532] [django.request:124] [exception:handle_uncaught_exception] [ERROR]- Internal Server Error: /project/
Traceback (most recent call last):
  File "C:\Python27\lib\site-packages\django\core\handlers\exception.py", line 39, in inner
    response = get_response(request)
  File "C:\Python27\lib\site-packages\django\core\handlers\base.py", line 187, in _get_response
    response = self.process_exception_by_middleware(e, request)
  File "C:\Python27\lib\site-packages\django\core\handlers\base.py", line 185, in _get_response
    response = wrapped_callback(request, *callback_args, **callback_kwargs)
  File "C:\Python27\lib\site-packages\django\views\decorators\csrf.py", line 58, in wrapped_view
    return view_func(*args, **kwargs)
  File "D:\eclipsworkdir\Automation_Platform\autoDjango\views.py", line 41, in project
    return render(request, 'html/proect_list.html', locals())
  File "C:\Python27\lib\site-packages\django\shortcuts.py", line 30, in render
    content = loader.render_to_string(template_name, context, request, using=using)
  File "C:\Python27\lib\site-packages\django\template\loader.py", line 67, in render_to_string
    template = get_template(template_name, using=using)
  File "C:\Python27\lib\site-packages\django\template\loader.py", line 25, in get_template
    raise TemplateDoesNotExist(template_name, chain=chain)
TemplateDoesNotExist: html/project_list.html
2016-11-07 09:35:32,171 [Thread-42:7972] [django.request:124] [exception:handle_uncaught_exception] [ERROR]- Internal Server Error: /project/
Traceback (most recent call last):
  File "C:\Python27\lib\site-packages\django\core\handlers\exception.py", line 39, in inner
    response = get_response(request)
  File "C:\Python27\lib\site-packages\django\core\handlers\base.py", line 187, in _get_response
    response = self.process_exception_by_middleware(e, request)
  File "C:\Python27\lib\site-packages\django\core\handlers\base.py", line 185, in _get_response
    response = wrapped_callback(request, *callback_args, **callback_kwargs)
  File "C:\Python27\lib\site-packages\django\views\decorators\csrf.py", line 58, in wrapped_view
    return view_func(*args, **kwargs)
  File "D:\eclipsworkdir\Automation_Platform\autoDjango\views.py", line 41, in project
    return render(request, 'html/proect_list.html', locals())
  File "C:\Python27\lib\site-packages\django\shortcuts.py", line 30, in render
    content = loader.render_to_string(template_name, context, request, using=using)
  File "C:\Python27\lib\site-packages\django\template\loader.py", line 67, in render_to_string
    template = get_template(template_name, using=using)
  File "C:\Python27\lib\site-packages\django\template\loader.py", line 25, in get_template
    raise TemplateDoesNotExist(template_name, chain=chain)
TemplateDoesNotExist: html/project_list.html
2016-11-07 09:35:42,680 [Thread-82:7000] [django.request:124] [exception:handle_uncaught_exception] [ERROR]- Internal Server Error: /project/
Traceback (most recent call last):
  File "C:\Python27\lib\site-packages\django\core\handlers\exception.py", line 39, in inner
    response = get_response(request)
  File "C:\Python27\lib\site-packages\django\core\handlers\base.py", line 187, in _get_response
    response = self.process_exception_by_middleware(e, request)
  File "C:\Python27\lib\site-packages\django\core\handlers\base.py", line 185, in _get_response
    response = wrapped_callback(request, *callback_args, **callback_kwargs)
  File "C:\Python27\lib\site-packages\django\views\decorators\csrf.py", line 58, in wrapped_view
    return view_func(*args, **kwargs)
  File "D:\eclipsworkdir\Automation_Platform\autoDjango\views.py", line 41, in project
    return render(request, 'html/proect_list.html', locals())
  File "C:\Python27\lib\site-packages\django\shortcuts.py", line 30, in render
    content = loader.render_to_string(template_name, context, request, using=using)
  File "C:\Python27\lib\site-packages\django\template\loader.py", line 67, in render_to_string
    template = get_template(template_name, using=using)
  File "C:\Python27\lib\site-packages\django\template\loader.py", line 25, in get_template
    raise TemplateDoesNotExist(template_name, chain=chain)
TemplateDoesNotExist: html/project_list.html
