2017-06-24 20:40:16,049 [Thread-132:12092] [django.request:124] [exception:handle_uncaught_exception] [ERROR]- Internal Server Error: /add_scenario/
Traceback (most recent call last):
  File "C:\Python27\lib\site-packages\django\core\handlers\exception.py", line 39, in inner
    response = get_response(request)
  File "C:\Python27\lib\site-packages\django\core\handlers\base.py", line 187, in _get_response
    response = self.process_exception_by_middleware(e, request)
  File "C:\Python27\lib\site-packages\django\core\handlers\base.py", line 185, in _get_response
    response = wrapped_callback(request, *callback_args, **callback_kwargs)
  File "C:\Python27\lib\site-packages\django\views\decorators\csrf.py", line 58, in wrapped_view
    return view_func(*args, **kwargs)
  File "D:\eclipsworkdir\Automation_Platform\autoDjango\views.py", line 199, in add_case_scenario
    test_case_list = TestCase.objects.filter(project_id=pro_id)
  File "C:\Python27\lib\site-packages\django\db\models\manager.py", line 85, in manager_method
    return getattr(self.get_queryset(), name)(*args, **kwargs)
  File "C:\Python27\lib\site-packages\django\db\models\query.py", line 796, in filter
    return self._filter_or_exclude(False, *args, **kwargs)
  File "C:\Python27\lib\site-packages\django\db\models\query.py", line 814, in _filter_or_exclude
    clone.query.add_q(Q(*args, **kwargs))
  File "C:\Python27\lib\site-packages\django\db\models\sql\query.py", line 1227, in add_q
    clause, _ = self._add_q(q_object, self.used_aliases)
  File "C:\Python27\lib\site-packages\django\db\models\sql\query.py", line 1253, in _add_q
    allow_joins=allow_joins, split_subq=split_subq,
  File "C:\Python27\lib\site-packages\django\db\models\sql\query.py", line 1183, in build_filter
    condition = lookup_class(lhs, value)
  File "C:\Python27\lib\site-packages\django\db\models\lookups.py", line 19, in __init__
    self.rhs = self.get_prep_lookup()
  File "C:\Python27\lib\site-packages\django\db\models\fields\related_lookups.py", line 100, in get_prep_lookup
    self.rhs = target_field.get_prep_value(self.rhs)
  File "C:\Python27\lib\site-packages\django\db\models\fields\__init__.py", line 946, in get_prep_value
    return int(value)
ValueError: invalid literal for int() with base 10: ''
2017-06-24 20:40:20,401 [Thread-138:9368] [django.request:124] [exception:handle_uncaught_exception] [ERROR]- Internal Server Error: /add_scenario/
Traceback (most recent call last):
  File "C:\Python27\lib\site-packages\django\core\handlers\exception.py", line 39, in inner
    response = get_response(request)
  File "C:\Python27\lib\site-packages\django\core\handlers\base.py", line 187, in _get_response
    response = self.process_exception_by_middleware(e, request)
  File "C:\Python27\lib\site-packages\django\core\handlers\base.py", line 185, in _get_response
    response = wrapped_callback(request, *callback_args, **callback_kwargs)
  File "C:\Python27\lib\site-packages\django\views\decorators\csrf.py", line 58, in wrapped_view
    return view_func(*args, **kwargs)
  File "D:\eclipsworkdir\Automation_Platform\autoDjango\views.py", line 199, in add_case_scenario
    test_case_list = TestCase.objects.filter(project_id=pro_id)
  File "C:\Python27\lib\site-packages\django\db\models\manager.py", line 85, in manager_method
    return getattr(self.get_queryset(), name)(*args, **kwargs)
  File "C:\Python27\lib\site-packages\django\db\models\query.py", line 796, in filter
    return self._filter_or_exclude(False, *args, **kwargs)
  File "C:\Python27\lib\site-packages\django\db\models\query.py", line 814, in _filter_or_exclude
    clone.query.add_q(Q(*args, **kwargs))
  File "C:\Python27\lib\site-packages\django\db\models\sql\query.py", line 1227, in add_q
    clause, _ = self._add_q(q_object, self.used_aliases)
  File "C:\Python27\lib\site-packages\django\db\models\sql\query.py", line 1253, in _add_q
    allow_joins=allow_joins, split_subq=split_subq,
  File "C:\Python27\lib\site-packages\django\db\models\sql\query.py", line 1183, in build_filter
    condition = lookup_class(lhs, value)
  File "C:\Python27\lib\site-packages\django\db\models\lookups.py", line 19, in __init__
    self.rhs = self.get_prep_lookup()
  File "C:\Python27\lib\site-packages\django\db\models\fields\related_lookups.py", line 100, in get_prep_lookup
    self.rhs = target_field.get_prep_value(self.rhs)
  File "C:\Python27\lib\site-packages\django\db\models\fields\__init__.py", line 946, in get_prep_value
    return int(value)
ValueError: invalid literal for int() with base 10: ''
2017-06-24 20:40:49,407 [Thread-163:7848] [django.request:124] [exception:handle_uncaught_exception] [ERROR]- Internal Server Error: /add_scenario/
Traceback (most recent call last):
  File "C:\Python27\lib\site-packages\django\core\handlers\exception.py", line 39, in inner
    response = get_response(request)
  File "C:\Python27\lib\site-packages\django\core\handlers\base.py", line 187, in _get_response
    response = self.process_exception_by_middleware(e, request)
  File "C:\Python27\lib\site-packages\django\core\handlers\base.py", line 185, in _get_response
    response = wrapped_callback(request, *callback_args, **callback_kwargs)
  File "C:\Python27\lib\site-packages\django\views\decorators\csrf.py", line 58, in wrapped_view
    return view_func(*args, **kwargs)
  File "D:\eclipsworkdir\Automation_Platform\autoDjango\views.py", line 199, in add_case_scenario
    test_case_list = TestCase.objects.filter(project_id=pro_id)
  File "C:\Python27\lib\site-packages\django\db\models\manager.py", line 85, in manager_method
    return getattr(self.get_queryset(), name)(*args, **kwargs)
  File "C:\Python27\lib\site-packages\django\db\models\query.py", line 796, in filter
    return self._filter_or_exclude(False, *args, **kwargs)
  File "C:\Python27\lib\site-packages\django\db\models\query.py", line 814, in _filter_or_exclude
    clone.query.add_q(Q(*args, **kwargs))
  File "C:\Python27\lib\site-packages\django\db\models\sql\query.py", line 1227, in add_q
    clause, _ = self._add_q(q_object, self.used_aliases)
  File "C:\Python27\lib\site-packages\django\db\models\sql\query.py", line 1253, in _add_q
    allow_joins=allow_joins, split_subq=split_subq,
  File "C:\Python27\lib\site-packages\django\db\models\sql\query.py", line 1183, in build_filter
    condition = lookup_class(lhs, value)
  File "C:\Python27\lib\site-packages\django\db\models\lookups.py", line 19, in __init__
    self.rhs = self.get_prep_lookup()
  File "C:\Python27\lib\site-packages\django\db\models\fields\related_lookups.py", line 100, in get_prep_lookup
    self.rhs = target_field.get_prep_value(self.rhs)
  File "C:\Python27\lib\site-packages\django\db\models\fields\__init__.py", line 946, in get_prep_value
    return int(value)
ValueError: invalid literal for int() with base 10: ''
2017-06-24 20:40:56,331 [Thread-169:1776] [django.request:124] [exception:handle_uncaught_exception] [ERROR]- Internal Server Error: /add_scenario/
Traceback (most recent call last):
  File "C:\Python27\lib\site-packages\django\core\handlers\exception.py", line 39, in inner
    response = get_response(request)
  File "C:\Python27\lib\site-packages\django\core\handlers\base.py", line 187, in _get_response
    response = self.process_exception_by_middleware(e, request)
  File "C:\Python27\lib\site-packages\django\core\handlers\base.py", line 185, in _get_response
    response = wrapped_callback(request, *callback_args, **callback_kwargs)
  File "C:\Python27\lib\site-packages\django\views\decorators\csrf.py", line 58, in wrapped_view
    return view_func(*args, **kwargs)
  File "D:\eclipsworkdir\Automation_Platform\autoDjango\views.py", line 199, in add_case_scenario
    test_case_list = TestCase.objects.filter(project_id=pro_id)
  File "C:\Python27\lib\site-packages\django\db\models\manager.py", line 85, in manager_method
    return getattr(self.get_queryset(), name)(*args, **kwargs)
  File "C:\Python27\lib\site-packages\django\db\models\query.py", line 796, in filter
    return self._filter_or_exclude(False, *args, **kwargs)
  File "C:\Python27\lib\site-packages\django\db\models\query.py", line 814, in _filter_or_exclude
    clone.query.add_q(Q(*args, **kwargs))
  File "C:\Python27\lib\site-packages\django\db\models\sql\query.py", line 1227, in add_q
    clause, _ = self._add_q(q_object, self.used_aliases)
  File "C:\Python27\lib\site-packages\django\db\models\sql\query.py", line 1253, in _add_q
    allow_joins=allow_joins, split_subq=split_subq,
  File "C:\Python27\lib\site-packages\django\db\models\sql\query.py", line 1183, in build_filter
    condition = lookup_class(lhs, value)
  File "C:\Python27\lib\site-packages\django\db\models\lookups.py", line 19, in __init__
    self.rhs = self.get_prep_lookup()
  File "C:\Python27\lib\site-packages\django\db\models\fields\related_lookups.py", line 100, in get_prep_lookup
    self.rhs = target_field.get_prep_value(self.rhs)
  File "C:\Python27\lib\site-packages\django\db\models\fields\__init__.py", line 946, in get_prep_value
    return int(value)
ValueError: invalid literal for int() with base 10: ''
2017-06-24 20:43:29,976 [Thread-226:9380] [django.request:124] [exception:handle_uncaught_exception] [ERROR]- Internal Server Error: /add_scenario/
Traceback (most recent call last):
  File "C:\Python27\lib\site-packages\django\core\handlers\exception.py", line 39, in inner
    response = get_response(request)
  File "C:\Python27\lib\site-packages\django\core\handlers\base.py", line 187, in _get_response
    response = self.process_exception_by_middleware(e, request)
  File "C:\Python27\lib\site-packages\django\core\handlers\base.py", line 185, in _get_response
    response = wrapped_callback(request, *callback_args, **callback_kwargs)
  File "C:\Python27\lib\site-packages\django\views\decorators\csrf.py", line 58, in wrapped_view
    return view_func(*args, **kwargs)
  File "D:\eclipsworkdir\Automation_Platform\autoDjango\views.py", line 199, in add_case_scenario
    test_case_list = TestCase.objects.filter(project_id=pro_id)
  File "C:\Python27\lib\site-packages\django\db\models\manager.py", line 85, in manager_method
    return getattr(self.get_queryset(), name)(*args, **kwargs)
  File "C:\Python27\lib\site-packages\django\db\models\query.py", line 796, in filter
    return self._filter_or_exclude(False, *args, **kwargs)
  File "C:\Python27\lib\site-packages\django\db\models\query.py", line 814, in _filter_or_exclude
    clone.query.add_q(Q(*args, **kwargs))
  File "C:\Python27\lib\site-packages\django\db\models\sql\query.py", line 1227, in add_q
    clause, _ = self._add_q(q_object, self.used_aliases)
  File "C:\Python27\lib\site-packages\django\db\models\sql\query.py", line 1253, in _add_q
    allow_joins=allow_joins, split_subq=split_subq,
  File "C:\Python27\lib\site-packages\django\db\models\sql\query.py", line 1183, in build_filter
    condition = lookup_class(lhs, value)
  File "C:\Python27\lib\site-packages\django\db\models\lookups.py", line 19, in __init__
    self.rhs = self.get_prep_lookup()
  File "C:\Python27\lib\site-packages\django\db\models\fields\related_lookups.py", line 100, in get_prep_lookup
    self.rhs = target_field.get_prep_value(self.rhs)
  File "C:\Python27\lib\site-packages\django\db\models\fields\__init__.py", line 946, in get_prep_value
    return int(value)
ValueError: invalid literal for int() with base 10: ''
2017-06-24 22:12:52,615 [Thread-281:6976] [django.request:124] [exception:handle_uncaught_exception] [ERROR]- Internal Server Error: /add_scenario/
Traceback (most recent call last):
  File "C:\Python27\lib\site-packages\django\core\handlers\exception.py", line 39, in inner
    response = get_response(request)
  File "C:\Python27\lib\site-packages\django\core\handlers\base.py", line 187, in _get_response
    response = self.process_exception_by_middleware(e, request)
  File "C:\Python27\lib\site-packages\django\core\handlers\base.py", line 185, in _get_response
    response = wrapped_callback(request, *callback_args, **callback_kwargs)
  File "C:\Python27\lib\site-packages\django\views\decorators\csrf.py", line 58, in wrapped_view
    return view_func(*args, **kwargs)
  File "D:\eclipsworkdir\Automation_Platform\autoDjango\views.py", line 199, in add_case_scenario
    test_case_list = TestCase.objects.filter(project_id=pro_id)
  File "C:\Python27\lib\site-packages\django\db\models\manager.py", line 85, in manager_method
    return getattr(self.get_queryset(), name)(*args, **kwargs)
  File "C:\Python27\lib\site-packages\django\db\models\query.py", line 796, in filter
    return self._filter_or_exclude(False, *args, **kwargs)
  File "C:\Python27\lib\site-packages\django\db\models\query.py", line 814, in _filter_or_exclude
    clone.query.add_q(Q(*args, **kwargs))
  File "C:\Python27\lib\site-packages\django\db\models\sql\query.py", line 1227, in add_q
    clause, _ = self._add_q(q_object, self.used_aliases)
  File "C:\Python27\lib\site-packages\django\db\models\sql\query.py", line 1253, in _add_q
    allow_joins=allow_joins, split_subq=split_subq,
  File "C:\Python27\lib\site-packages\django\db\models\sql\query.py", line 1183, in build_filter
    condition = lookup_class(lhs, value)
  File "C:\Python27\lib\site-packages\django\db\models\lookups.py", line 19, in __init__
    self.rhs = self.get_prep_lookup()
  File "C:\Python27\lib\site-packages\django\db\models\fields\related_lookups.py", line 100, in get_prep_lookup
    self.rhs = target_field.get_prep_value(self.rhs)
  File "C:\Python27\lib\site-packages\django\db\models\fields\__init__.py", line 946, in get_prep_value
    return int(value)
ValueError: invalid literal for int() with base 10: ''
2017-06-24 22:17:14,315 [Thread-387:6716] [django.request:124] [exception:handle_uncaught_exception] [ERROR]- Internal Server Error: /add_case/
Traceback (most recent call last):
  File "C:\Python27\lib\site-packages\django\core\handlers\exception.py", line 39, in inner
    response = get_response(request)
  File "C:\Python27\lib\site-packages\django\core\handlers\base.py", line 187, in _get_response
    response = self.process_exception_by_middleware(e, request)
  File "C:\Python27\lib\site-packages\django\core\handlers\base.py", line 185, in _get_response
    response = wrapped_callback(request, *callback_args, **callback_kwargs)
  File "C:\Python27\lib\site-packages\django\views\decorators\csrf.py", line 58, in wrapped_view
    return view_func(*args, **kwargs)
  File "D:\eclipsworkdir\Automation_Platform\autoDjango\views.py", line 278, in add_case
    import_case = Project.objects.get(pk=pro_id).testcase_set.all()
  File "C:\Python27\lib\site-packages\django\db\models\manager.py", line 85, in manager_method
    return getattr(self.get_queryset(), name)(*args, **kwargs)
  File "C:\Python27\lib\site-packages\django\db\models\query.py", line 376, in get
    clone = self.filter(*args, **kwargs)
  File "C:\Python27\lib\site-packages\django\db\models\query.py", line 796, in filter
    return self._filter_or_exclude(False, *args, **kwargs)
  File "C:\Python27\lib\site-packages\django\db\models\query.py", line 814, in _filter_or_exclude
    clone.query.add_q(Q(*args, **kwargs))
  File "C:\Python27\lib\site-packages\django\db\models\sql\query.py", line 1227, in add_q
    clause, _ = self._add_q(q_object, self.used_aliases)
  File "C:\Python27\lib\site-packages\django\db\models\sql\query.py", line 1253, in _add_q
    allow_joins=allow_joins, split_subq=split_subq,
  File "C:\Python27\lib\site-packages\django\db\models\sql\query.py", line 1187, in build_filter
    condition = self.build_lookup(lookups, col, value)
  File "C:\Python27\lib\site-packages\django\db\models\sql\query.py", line 1083, in build_lookup
    return final_lookup(lhs, rhs)
  File "C:\Python27\lib\site-packages\django\db\models\lookups.py", line 19, in __init__
    self.rhs = self.get_prep_lookup()
  File "C:\Python27\lib\site-packages\django\db\models\lookups.py", line 59, in get_prep_lookup
    return self.lhs.output_field.get_prep_value(self.rhs)
  File "C:\Python27\lib\site-packages\django\db\models\fields\__init__.py", line 946, in get_prep_value
    return int(value)
ValueError: invalid literal for int() with base 10: ''
2017-06-24 22:53:36,357 [Thread-396:6596] [django.request:124] [exception:handle_uncaught_exception] [ERROR]- Internal Server Error: /add_case/
Traceback (most recent call last):
  File "C:\Python27\lib\site-packages\django\core\handlers\exception.py", line 39, in inner
    response = get_response(request)
  File "C:\Python27\lib\site-packages\django\core\handlers\base.py", line 187, in _get_response
    response = self.process_exception_by_middleware(e, request)
  File "C:\Python27\lib\site-packages\django\core\handlers\base.py", line 185, in _get_response
    response = wrapped_callback(request, *callback_args, **callback_kwargs)
  File "C:\Python27\lib\site-packages\django\views\decorators\csrf.py", line 58, in wrapped_view
    return view_func(*args, **kwargs)
  File "D:\eclipsworkdir\Automation_Platform\autoDjango\views.py", line 278, in add_case
    import_case = Project.objects.get(pk=pro_id).testcase_set.all()
  File "C:\Python27\lib\site-packages\django\db\models\manager.py", line 85, in manager_method
    return getattr(self.get_queryset(), name)(*args, **kwargs)
  File "C:\Python27\lib\site-packages\django\db\models\query.py", line 376, in get
    clone = self.filter(*args, **kwargs)
  File "C:\Python27\lib\site-packages\django\db\models\query.py", line 796, in filter
    return self._filter_or_exclude(False, *args, **kwargs)
  File "C:\Python27\lib\site-packages\django\db\models\query.py", line 814, in _filter_or_exclude
    clone.query.add_q(Q(*args, **kwargs))
  File "C:\Python27\lib\site-packages\django\db\models\sql\query.py", line 1227, in add_q
    clause, _ = self._add_q(q_object, self.used_aliases)
  File "C:\Python27\lib\site-packages\django\db\models\sql\query.py", line 1253, in _add_q
    allow_joins=allow_joins, split_subq=split_subq,
  File "C:\Python27\lib\site-packages\django\db\models\sql\query.py", line 1187, in build_filter
    condition = self.build_lookup(lookups, col, value)
  File "C:\Python27\lib\site-packages\django\db\models\sql\query.py", line 1083, in build_lookup
    return final_lookup(lhs, rhs)
  File "C:\Python27\lib\site-packages\django\db\models\lookups.py", line 19, in __init__
    self.rhs = self.get_prep_lookup()
  File "C:\Python27\lib\site-packages\django\db\models\lookups.py", line 59, in get_prep_lookup
    return self.lhs.output_field.get_prep_value(self.rhs)
  File "C:\Python27\lib\site-packages\django\db\models\fields\__init__.py", line 946, in get_prep_value
    return int(value)
ValueError: invalid literal for int() with base 10: ''
