2016-09-24 00:16:44,750 [Thread-118:16616] [django.request:124] [exception:handle_uncaught_exception] [ERROR]- Internal Server Error: /element/
Traceback (most recent call last):
  File "D:\python\Python27\Python27\lib\site-packages\django\core\handlers\exception.py", line 39, in inner
    response = get_response(request)
  File "D:\python\Python27\Python27\lib\site-packages\django\core\handlers\base.py", line 187, in _get_response
    response = self.process_exception_by_middleware(e, request)
  File "D:\python\Python27\Python27\lib\site-packages\django\core\handlers\base.py", line 185, in _get_response
    response = wrapped_callback(request, *callback_args, **callback_kwargs)
  File "D:\python\Python27\Python27\lib\site-packages\django\views\decorators\csrf.py", line 58, in wrapped_view
    return view_func(*args, **kwargs)
  File "D:\eclipsworkdir\Automation_Platform\hero\views.py", line 95, in element
    element_list = Project.objects.get(pk=project_id).element_set.all()
  File "D:\python\Python27\Python27\lib\site-packages\django\db\models\manager.py", line 85, in manager_method
    return getattr(self.get_queryset(), name)(*args, **kwargs)
  File "D:\python\Python27\Python27\lib\site-packages\django\db\models\query.py", line 376, in get
    clone = self.filter(*args, **kwargs)
  File "D:\python\Python27\Python27\lib\site-packages\django\db\models\query.py", line 794, in filter
    return self._filter_or_exclude(False, *args, **kwargs)
  File "D:\python\Python27\Python27\lib\site-packages\django\db\models\query.py", line 812, in _filter_or_exclude
    clone.query.add_q(Q(*args, **kwargs))
  File "D:\python\Python27\Python27\lib\site-packages\django\db\models\sql\query.py", line 1227, in add_q
    clause, _ = self._add_q(q_object, self.used_aliases)
  File "D:\python\Python27\Python27\lib\site-packages\django\db\models\sql\query.py", line 1253, in _add_q
    allow_joins=allow_joins, split_subq=split_subq,
  File "D:\python\Python27\Python27\lib\site-packages\django\db\models\sql\query.py", line 1187, in build_filter
    condition = self.build_lookup(lookups, col, value)
  File "D:\python\Python27\Python27\lib\site-packages\django\db\models\sql\query.py", line 1083, in build_lookup
    return final_lookup(lhs, rhs)
  File "D:\python\Python27\Python27\lib\site-packages\django\db\models\lookups.py", line 19, in __init__
    self.rhs = self.get_prep_lookup()
  File "D:\python\Python27\Python27\lib\site-packages\django\db\models\lookups.py", line 59, in get_prep_lookup
    return self.lhs.output_field.get_prep_value(self.rhs)
  File "D:\python\Python27\Python27\lib\site-packages\django\db\models\fields\__init__.py", line 946, in get_prep_value
    return int(value)
ValueError: invalid literal for int() with base 10: 'undefined'
